  Running command git clone --filter=blob:none --quiet https://github.com/huggingface/peft.git /tmp/sdim_34-89420/pip-req-build-zm2qc71j
  Running command git clone --filter=blob:none --quiet https://github.com/huggingface/transformers.git /tmp/sdim_34-89420/pip-req-build-l383g3af
Unused kwargs: ['bnb_8bit_compute_dtype']. These kwargs are not used in <class 'transformers.utils.quantization_config.BitsAndBytesConfig'>.
Traceback (most recent call last):
  File "/tmp/sdim_34-89420/venv/lib/python3.10/site-packages/huggingface_hub/utils/_http.py", line 406, in hf_raise_for_status
    response.raise_for_status()
  File "/tmp/sdim_34-89420/venv/lib/python3.10/site-packages/requests/models.py", line 1024, in raise_for_status
    raise HTTPError(http_error_msg, response=self)
requests.exceptions.HTTPError: 401 Client Error: Unauthorized for url: https://huggingface.co/DeepSeek-R1-Distill-Qwen-32B/resolve/main/tokenizer_config.json

The above exception was the direct cause of the following exception:

Traceback (most recent call last):
  File "/tmp/sdim_34-89420/venv/lib/python3.10/site-packages/transformers/utils/hub.py", line 363, in cached_file
    resolved_file = hf_hub_download(
  File "/tmp/sdim_34-89420/venv/lib/python3.10/site-packages/huggingface_hub/utils/_validators.py", line 114, in _inner_fn
    return fn(*args, **kwargs)
  File "/tmp/sdim_34-89420/venv/lib/python3.10/site-packages/huggingface_hub/file_download.py", line 860, in hf_hub_download
    return _hf_hub_download_to_cache_dir(
  File "/tmp/sdim_34-89420/venv/lib/python3.10/site-packages/huggingface_hub/file_download.py", line 967, in _hf_hub_download_to_cache_dir
    _raise_on_head_call_error(head_call_error, force_download, local_files_only)
  File "/tmp/sdim_34-89420/venv/lib/python3.10/site-packages/huggingface_hub/file_download.py", line 1482, in _raise_on_head_call_error
    raise head_call_error
  File "/tmp/sdim_34-89420/venv/lib/python3.10/site-packages/huggingface_hub/file_download.py", line 1374, in _get_metadata_or_catch_error
    metadata = get_hf_file_metadata(
  File "/tmp/sdim_34-89420/venv/lib/python3.10/site-packages/huggingface_hub/utils/_validators.py", line 114, in _inner_fn
    return fn(*args, **kwargs)
  File "/tmp/sdim_34-89420/venv/lib/python3.10/site-packages/huggingface_hub/file_download.py", line 1294, in get_hf_file_metadata
    r = _request_wrapper(
  File "/tmp/sdim_34-89420/venv/lib/python3.10/site-packages/huggingface_hub/file_download.py", line 278, in _request_wrapper
    response = _request_wrapper(
  File "/tmp/sdim_34-89420/venv/lib/python3.10/site-packages/huggingface_hub/file_download.py", line 302, in _request_wrapper
    hf_raise_for_status(response)
  File "/tmp/sdim_34-89420/venv/lib/python3.10/site-packages/huggingface_hub/utils/_http.py", line 454, in hf_raise_for_status
    raise _format(RepositoryNotFoundError, message, response) from e
huggingface_hub.errors.RepositoryNotFoundError: 401 Client Error. (Request ID: Root=1-679fddaa-2ec32ea34394e6c66a4a7f3f;e3810c02-677b-4193-ad45-54506e06af8b)

Repository Not Found for url: https://huggingface.co/DeepSeek-R1-Distill-Qwen-32B/resolve/main/tokenizer_config.json.
Please make sure you specified the correct `repo_id` and `repo_type`.
If you are trying to access a private or gated repo, make sure you are authenticated.
Invalid username or password.

The above exception was the direct cause of the following exception:

Traceback (most recent call last):
  File "/usr/users/sdim/sdim_34/lora-llm/lora_training.py", line 28, in <module>
    tokenizer = AutoTokenizer.from_pretrained(model_name)
  File "/tmp/sdim_34-89420/venv/lib/python3.10/site-packages/transformers/models/auto/tokenization_auto.py", line 881, in from_pretrained
    tokenizer_config = get_tokenizer_config(pretrained_model_name_or_path, **kwargs)
  File "/tmp/sdim_34-89420/venv/lib/python3.10/site-packages/transformers/models/auto/tokenization_auto.py", line 713, in get_tokenizer_config
    resolved_config_file = cached_file(
  File "/tmp/sdim_34-89420/venv/lib/python3.10/site-packages/transformers/utils/hub.py", line 386, in cached_file
    raise EnvironmentError(
OSError: DeepSeek-R1-Distill-Qwen-32B is not a local folder and is not a valid model identifier listed on 'https://huggingface.co/models'
If this is a private repository, make sure to pass a token having permission to this repo either by logging in with `huggingface-cli login` or by passing `token=<your_token>`
